<?xml version="1.0" ?>
<!-- =================================================================================== -->
<!-- |    This document was autogenerated by xacro from table_kinova.urdf.xacro        | -->
<!-- |    EDITING THIS FILE BY HAND IS NOT RECOMMENDED                                 | -->
<!-- =================================================================================== -->
<robot name="table_kinova" xmlns:body="http://playerstage.sourceforge.net/gazebo/xmlschema/#body" xmlns:controller="http://playerstage.sourceforge.net/gazebo/xmlschema/#controller" xmlns:gazebo="http://playerstage.sourceforge.net/gazebo/xmlschema/#gz" xmlns:geom="http://playerstage.sourceforge.net/gazebo/xmlschema/#geom" xmlns:interface="http://playerstage.sourceforge.net/gazebo/xmlschema/#interface" xmlns:joint="http://playerstage.sourceforge.net/gazebo/xmlschema/#joint" xmlns:model="http://playerstage.sourceforge.net/gazebo/xmlschema/#model" xmlns:physics="http://playerstage.sourceforge.net/gazebo/xmlschema/#physics" xmlns:renderable="http://playerstage.sourceforge.net/gazebo/xmlschema/#renderable" xmlns:rendering="http://playerstage.sourceforge.net/gazebo/xmlschema/#rendering" xmlns:sensor="http://playerstage.sourceforge.net/gazebo/xmlschema/#sensor" xmlns:xacro="http://ros.org/wiki/xacro" xmlns:xi="http://www.w3.org/2001/XInclude">
  <!-- include urdf -->
  <!-- links      		mesh_no
   base           		0
   shoulder       		1
   arm            		2
   forearm        		3
   wrist          		4
   arm_mico       		5
   arm_half1 (7dof)		6
   arm_half2 (7dof)		7
   wrist_spherical_1  8
   wrist_spherical_2  9

   hand 3 finger  		55
   hand_2finger   		56
   finger_proximal		57
   finger_distal      58 
-->
  <!-- links      		mesh_no
   base           		0
   shoulder       		1
   arm            		2
   forearm        		3
   wrist          		4
   arm_mico       		5
   arm_half1 (7dof)		6
   arm_half2 (7dof)		7
   wrist_spherical_1  8
   wrist_spherical_2  9

   hand 3 finger  		55
   hand_2finger   		56
   finger_proximal		57
   finger_distal      58 
-->
  <!-- Import all Gazebo-customization elements -->
  <!--Used for conditional arguments for setting inertial parameters
        base 0, shoulder 1, arm 2, forearm 3, wrist 4, arm_mico 5,
        arm_half1 (7dof)	6, arm_half2 (7dof) 7, wrist_spherical_1  8, wrist_spherical_2  9
        fore_arm_mico 10,
        hand 3 finger 55, hand_2finger 56, finger_proximal 57, finger_distal 58 
    -->
  <link name="root">
    <visual>
      <origin rpy="0 0 0" xyz="0 0 0"/>
      <geometry>
        <box size="0 0 0"/>
      </geometry>
      <!--<material name="Black" /> -->
    </visual>
    <collision>
      <origin rpy="0 0 0" xyz="0 0 0"/>
      <geometry>
        <box size="0 0 0"/>
      </geometry>
    </collision>
  </link>
  <!-- for gazebo 
  <link name="world"/>
  
  <joint name="connect_root_and_world" type="fixed">
    <child link="root" />
    <parent link="world" />
    <origin xyz="0 0 0" rpy="0 0 0" />    
  </joint>  -->
  <!-- ros_control plugin -->
  <gazebo>
    <plugin filename="libgazebo_ros_control.so" name="gazebo_ros_control">
      <robotNamespace>j2s7s300</robotNamespace>
      <robotSimType>gazebo_ros_control/DefaultRobotHWSim</robotSimType>
    </plugin>
  </gazebo>
  <link name="j2s7s300_link_base">
    <visual>
      <geometry>
        <mesh filename="package://kinova_description/meshes/base.dae"/>
      </geometry>
      <material name="carbon_fiber">
        <color rgba="0.792156862745098 0.819607843137255 0.933333333333333 1"/>
      </material>
    </visual>
    <!-- Adding ring to the model -->
    <collision>
      <geometry>
        <mesh filename="package://kinova_description/meshes/base.dae"/>
      </geometry>
    </collision>
    <!-- base = 0 -->
    <inertial>
      <mass value="0.46784"/>
      <origin rpy="0 0 0" xyz="0 0 0.1255"/>
      <!-- z Axis -->
      <inertia ixx="0.000951270861568" ixy="0" ixz="0" iyy="0.000951270861568" iyz="0" izz="0.000374272"/>
      <!-- y Axis -->
      <!-- x Axis -->
    </inertial>
    <!-- shoulder = 1 -->
    <!-- arm = 2-->
    <!-- forearm = 3 -->
    <!-- wrist = 4 -->
    <!--arm_mico       		5 -->
    <!--   arm_half1 (7dof)		6 -->
    <!--   arm_half2 (7dof)		7 -->
    <!--   wrist_spherical_1  8 -->
    <!--   wrist_spherical_2  9 -->
    <!--   forearm_mico  10 -->
    <!-- hand 3 finger = 55 -->
    <!-- hand 2 finger = 56 -->
    <!-- finger_proximal = 57 -->
    <!-- finger_distal = 58 -->
  </link>
  <joint name="j2s7s300_joint_base" type="fixed">
    <parent link="root"/>
    <child link="j2s7s300_link_base"/>
    <axis xyz="0 0 0"/>
    <limit effort="2000" lower="0" upper="0" velocity="1"/>
    <origin rpy="0 0 0" xyz="0 0 0"/>
    <dynamics damping="0.0" friction="0.0"/>
  </joint>
  <link name="j2s7s300_link_1">
    <visual>
      <geometry>
        <mesh filename="package://kinova_description/meshes/shoulder.dae"/>
      </geometry>
      <material name="carbon_fiber">
        <color rgba="0.792156862745098 0.819607843137255 0.933333333333333 1"/>
      </material>
    </visual>
    <!-- Adding ring to the model -->
    <visual>
      <geometry>
        <mesh filename="package://kinova_description/meshes/ring_big.STL"/>
      </geometry>
    </visual>
    <collision>
      <geometry>
        <mesh filename="package://kinova_description/meshes/shoulder.dae"/>
      </geometry>
    </collision>
    <!-- base = 0 -->
    <!-- shoulder = 1 -->
    <inertial>
      <mass value="0.7477"/>
      <origin xyz="0 -0.002 -0.0605"/>
      <!-- z Axis -->
      <inertia ixx="0.00152031725204" ixy="0" ixz="0" iyy="0.00152031725204" iyz="0" izz="0.00059816"/>
      <!-- y Axis -->
      <!-- x Axis -->
    </inertial>
    <!-- arm = 2-->
    <!-- forearm = 3 -->
    <!-- wrist = 4 -->
    <!--arm_mico       		5 -->
    <!--   arm_half1 (7dof)		6 -->
    <!--   arm_half2 (7dof)		7 -->
    <!--   wrist_spherical_1  8 -->
    <!--   wrist_spherical_2  9 -->
    <!--   forearm_mico  10 -->
    <!-- hand 3 finger = 55 -->
    <!-- hand 2 finger = 56 -->
    <!-- finger_proximal = 57 -->
    <!-- finger_distal = 58 -->
  </link>
  <joint name="j2s7s300_joint_1" type="continuous">
    <parent link="j2s7s300_link_base"/>
    <child link="j2s7s300_link_1"/>
    <axis xyz="0 0 1"/>
    <limit effort="2000" lower="-6.28318530718" upper="6.28318530718" velocity="1"/>
    <origin rpy="0 3.14159265359 0" xyz="0 0 0.15675"/>
    <dynamics damping="0.0" friction="0.0"/>
  </joint>
  <transmission name="j2s7s300_joint_1_trans">
    <type>transmission_interface/SimpleTransmission</type>
    <joint name="j2s7s300_joint_1">
      <hardwareInterface>EffortJointInterface</hardwareInterface>
    </joint>
    <actuator name="j2s7s300_joint_1_actuator">
      <hardwareInterface>EffortJointInterface</hardwareInterface>
      <mechanicalReduction>160</mechanicalReduction>
    </actuator>
  </transmission>
  <link name="j2s7s300_link_2">
    <visual>
      <geometry>
        <mesh filename="package://kinova_description/meshes/arm_half_1.dae"/>
      </geometry>
      <material name="carbon_fiber">
        <color rgba="0.792156862745098 0.819607843137255 0.933333333333333 1"/>
      </material>
    </visual>
    <!-- Adding ring to the model -->
    <visual>
      <geometry>
        <mesh filename="package://kinova_description/meshes/ring_big.STL"/>
      </geometry>
    </visual>
    <collision>
      <geometry>
        <mesh filename="package://kinova_description/meshes/arm_half_1.dae"/>
      </geometry>
    </collision>
    <!-- base = 0 -->
    <!-- shoulder = 1 -->
    <!-- arm = 2-->
    <!-- forearm = 3 -->
    <!-- wrist = 4 -->
    <!--arm_mico       		5 -->
    <!--   arm_half1 (7dof)		6 -->
    <inertial>
      <mass value="0.8447"/>
      <origin xyz="0 -0.103563213 0"/>
      <!-- z Axis -->
      <!-- y Axis -->
      <inertia ixx="0.00247073761701" ixy="0" ixz="0" iyy="0.000380115" iyz="0" izz="0.00247073761701"/>
      <!-- x Axis -->
    </inertial>
    <!--   arm_half2 (7dof)		7 -->
    <!--   wrist_spherical_1  8 -->
    <!--   wrist_spherical_2  9 -->
    <!--   forearm_mico  10 -->
    <!-- hand 3 finger = 55 -->
    <!-- hand 2 finger = 56 -->
    <!-- finger_proximal = 57 -->
    <!-- finger_distal = 58 -->
  </link>
  <joint name="j2s7s300_joint_2" type="revolute">
    <parent link="j2s7s300_link_1"/>
    <child link="j2s7s300_link_2"/>
    <axis xyz="0 0 1"/>
    <limit effort="2000" lower="0.523598775598" upper="5.75958653158" velocity="1"/>
    <origin rpy="-1.57079632679 0 3.14159265359" xyz="0 0.0016 -0.11875"/>
    <dynamics damping="0.0" friction="0.0"/>
  </joint>
  <transmission name="j2s7s300_joint_2_trans">
    <type>transmission_interface/SimpleTransmission</type>
    <joint name="j2s7s300_joint_2">
      <hardwareInterface>EffortJointInterface</hardwareInterface>
    </joint>
    <actuator name="j2s7s300_joint_2_actuator">
      <hardwareInterface>EffortJointInterface</hardwareInterface>
      <mechanicalReduction>160</mechanicalReduction>
    </actuator>
  </transmission>
  <link name="j2s7s300_link_3">
    <visual>
      <geometry>
        <mesh filename="package://kinova_description/meshes/arm_half_2.dae"/>
      </geometry>
      <material name="carbon_fiber">
        <color rgba="0.792156862745098 0.819607843137255 0.933333333333333 1"/>
      </material>
    </visual>
    <!-- Adding ring to the model -->
    <visual>
      <geometry>
        <mesh filename="package://kinova_description/meshes/ring_big.STL"/>
      </geometry>
    </visual>
    <collision>
      <geometry>
        <mesh filename="package://kinova_description/meshes/arm_half_2.dae"/>
      </geometry>
    </collision>
    <!-- base = 0 -->
    <!-- shoulder = 1 -->
    <!-- arm = 2-->
    <!-- forearm = 3 -->
    <!-- wrist = 4 -->
    <!--arm_mico       		5 -->
    <!--   arm_half1 (7dof)		6 -->
    <!--   arm_half2 (7dof)		7 -->
    <inertial>
      <mass value="0.8447"/>
      <origin xyz="0 0 -0.1022447445"/>
      <!-- z Axis -->
      <inertia ixx="0.00247073761701" ixy="0" ixz="0" iyy="0.00247073761701" iyz="0" izz="0.000380115"/>
      <!-- y Axis -->
      <!-- x Axis -->
    </inertial>
    <!--   wrist_spherical_1  8 -->
    <!--   wrist_spherical_2  9 -->
    <!--   forearm_mico  10 -->
    <!-- hand 3 finger = 55 -->
    <!-- hand 2 finger = 56 -->
    <!-- finger_proximal = 57 -->
    <!-- finger_distal = 58 -->
  </link>
  <joint name="j2s7s300_joint_3" type="continuous">
    <parent link="j2s7s300_link_2"/>
    <child link="j2s7s300_link_3"/>
    <axis xyz="0 0 1"/>
    <limit effort="2000" lower="-6.28318530718" upper="6.28318530718" velocity="1"/>
    <origin rpy="-1.57079632679 0 0" xyz="0 -0.205 0"/>
    <dynamics damping="0.0" friction="0.0"/>
  </joint>
  <transmission name="j2s7s300_joint_3_trans">
    <type>transmission_interface/SimpleTransmission</type>
    <joint name="j2s7s300_joint_3">
      <hardwareInterface>EffortJointInterface</hardwareInterface>
    </joint>
    <actuator name="j2s7s300_joint_3_actuator">
      <hardwareInterface>EffortJointInterface</hardwareInterface>
      <mechanicalReduction>160</mechanicalReduction>
    </actuator>
  </transmission>
  <link name="j2s7s300_link_4">
    <visual>
      <geometry>
        <mesh filename="package://kinova_description/meshes/forearm.dae"/>
      </geometry>
      <material name="carbon_fiber">
        <color rgba="0.792156862745098 0.819607843137255 0.933333333333333 1"/>
      </material>
    </visual>
    <!-- Adding ring to the model -->
    <visual>
      <geometry>
        <mesh filename="package://kinova_description/meshes/ring_small.STL"/>
      </geometry>
    </visual>
    <collision>
      <geometry>
        <mesh filename="package://kinova_description/meshes/forearm.dae"/>
      </geometry>
    </collision>
    <!-- base = 0 -->
    <!-- shoulder = 1 -->
    <!-- arm = 2-->
    <!-- forearm = 3 -->
    <inertial>
      <mass value="0.6763"/>
      <origin xyz="0 0.081 -0.0086"/>
      <!-- z Axis -->
      <!-- y Axis -->
      <inertia ixx="0.00142022431908" ixy="0" ixz="0" iyy="0.000304335" iyz="0" izz="0.00142022431908"/>
      <!-- x Axis -->
    </inertial>
    <!-- wrist = 4 -->
    <!--arm_mico       		5 -->
    <!--   arm_half1 (7dof)		6 -->
    <!--   arm_half2 (7dof)		7 -->
    <!--   wrist_spherical_1  8 -->
    <!--   wrist_spherical_2  9 -->
    <!--   forearm_mico  10 -->
    <!-- hand 3 finger = 55 -->
    <!-- hand 2 finger = 56 -->
    <!-- finger_proximal = 57 -->
    <!-- finger_distal = 58 -->
  </link>
  <joint name="j2s7s300_joint_4" type="revolute">
    <parent link="j2s7s300_link_3"/>
    <child link="j2s7s300_link_4"/>
    <axis xyz="0 0 1"/>
    <limit effort="2000" lower="0.523598775598" upper="5.75958653158" velocity="1"/>
    <origin rpy="1.57079632679 0 3.14159265359" xyz="0 0 -0.205"/>
    <dynamics damping="0.0" friction="0.0"/>
  </joint>
  <transmission name="j2s7s300_joint_4_trans">
    <type>transmission_interface/SimpleTransmission</type>
    <joint name="j2s7s300_joint_4">
      <hardwareInterface>EffortJointInterface</hardwareInterface>
    </joint>
    <actuator name="j2s7s300_joint_4_actuator">
      <hardwareInterface>EffortJointInterface</hardwareInterface>
      <mechanicalReduction>160</mechanicalReduction>
    </actuator>
  </transmission>
  <link name="j2s7s300_link_5">
    <visual>
      <geometry>
        <mesh filename="package://kinova_description/meshes/wrist_spherical_1.dae"/>
      </geometry>
      <material name="carbon_fiber">
        <color rgba="0.792156862745098 0.819607843137255 0.933333333333333 1"/>
      </material>
    </visual>
    <!-- Adding ring to the model -->
    <visual>
      <geometry>
        <mesh filename="package://kinova_description/meshes/ring_small.STL"/>
      </geometry>
    </visual>
    <collision>
      <geometry>
        <mesh filename="package://kinova_description/meshes/wrist_spherical_1.dae"/>
      </geometry>
    </collision>
    <!-- base = 0 -->
    <!-- shoulder = 1 -->
    <!-- arm = 2-->
    <!-- forearm = 3 -->
    <!-- wrist = 4 -->
    <!--arm_mico       		5 -->
    <!--   arm_half1 (7dof)		6 -->
    <!--   arm_half2 (7dof)		7 -->
    <!--   wrist_spherical_1  8 -->
    <inertial>
      <mass value="0.463"/>
      <origin xyz="0 0.0028848942 -0.0541932613"/>
      <!-- z Axis -->
      <inertia ixx="0.0004321316048" ixy="0" ixz="0" iyy="0.0004321316048" iyz="0" izz="9.26e-05"/>
      <!-- y Axis -->
      <!-- x Axis -->
    </inertial>
    <!--   wrist_spherical_2  9 -->
    <!--   forearm_mico  10 -->
    <!-- hand 3 finger = 55 -->
    <!-- hand 2 finger = 56 -->
    <!-- finger_proximal = 57 -->
    <!-- finger_distal = 58 -->
  </link>
  <joint name="j2s7s300_joint_5" type="continuous">
    <parent link="j2s7s300_link_4"/>
    <child link="j2s7s300_link_5"/>
    <axis xyz="0 0 1"/>
    <limit effort="2000" lower="-6.28318530718" upper="6.28318530718" velocity="1"/>
    <origin rpy="-1.57079632679 0 3.14159265359" xyz="0 0.2073 -0.0114"/>
    <dynamics damping="0.0" friction="0.0"/>
  </joint>
  <transmission name="j2s7s300_joint_5_trans">
    <type>transmission_interface/SimpleTransmission</type>
    <joint name="j2s7s300_joint_5">
      <hardwareInterface>EffortJointInterface</hardwareInterface>
    </joint>
    <actuator name="j2s7s300_joint_5_actuator">
      <hardwareInterface>EffortJointInterface</hardwareInterface>
      <mechanicalReduction>160</mechanicalReduction>
    </actuator>
  </transmission>
  <link name="j2s7s300_link_6">
    <visual>
      <geometry>
        <mesh filename="package://kinova_description/meshes/wrist_spherical_2.dae"/>
      </geometry>
      <material name="carbon_fiber">
        <color rgba="0.792156862745098 0.819607843137255 0.933333333333333 1"/>
      </material>
    </visual>
    <!-- Adding ring to the model -->
    <visual>
      <geometry>
        <mesh filename="package://kinova_description/meshes/ring_small.STL"/>
      </geometry>
    </visual>
    <collision>
      <geometry>
        <mesh filename="package://kinova_description/meshes/wrist_spherical_2.dae"/>
      </geometry>
    </collision>
    <!-- base = 0 -->
    <!-- shoulder = 1 -->
    <!-- arm = 2-->
    <!-- forearm = 3 -->
    <!-- wrist = 4 -->
    <!--arm_mico       		5 -->
    <!--   arm_half1 (7dof)		6 -->
    <!--   arm_half2 (7dof)		7 -->
    <!--   wrist_spherical_1  8 -->
    <!--   wrist_spherical_2  9 -->
    <inertial>
      <mass value="0.463"/>
      <origin xyz="0 0.0497208855 -0.0028562765"/>
      <!-- z Axis -->
      <!-- y Axis -->
      <inertia ixx="0.0004321316048" ixy="0" ixz="0" iyy="9.26e-05" iyz="0" izz="0.0004321316048"/>
      <!-- x Axis -->
    </inertial>
    <!--   forearm_mico  10 -->
    <!-- hand 3 finger = 55 -->
    <!-- hand 2 finger = 56 -->
    <!-- finger_proximal = 57 -->
    <!-- finger_distal = 58 -->
  </link>
  <joint name="j2s7s300_joint_6" type="revolute">
    <parent link="j2s7s300_link_5"/>
    <child link="j2s7s300_link_6"/>
    <axis xyz="0 0 1"/>
    <limit effort="2000" lower="0.523598775598" upper="5.75958653158" velocity="1"/>
    <origin rpy="1.57079632679 0 3.14159265359" xyz="0 0 -0.10375"/>
    <dynamics damping="0.0" friction="0.0"/>
  </joint>
  <transmission name="j2s7s300_joint_6_trans">
    <type>transmission_interface/SimpleTransmission</type>
    <joint name="j2s7s300_joint_6">
      <hardwareInterface>EffortJointInterface</hardwareInterface>
    </joint>
    <actuator name="j2s7s300_joint_6_actuator">
      <hardwareInterface>EffortJointInterface</hardwareInterface>
      <mechanicalReduction>160</mechanicalReduction>
    </actuator>
  </transmission>
  <link name="j2s7s300_link_7">
    <visual>
      <geometry>
        <mesh filename="package://kinova_description/meshes/hand_3finger.dae"/>
      </geometry>
      <material name="carbon_fiber">
        <color rgba="0.792156862745098 0.819607843137255 0.933333333333333 1"/>
      </material>
    </visual>
    <!-- Adding ring to the model -->
    <visual>
      <geometry>
        <mesh filename="package://kinova_description/meshes/ring_small.STL"/>
      </geometry>
    </visual>
    <collision>
      <geometry>
        <mesh filename="package://kinova_description/meshes/hand_3finger.dae"/>
      </geometry>
    </collision>
    <!-- base = 0 -->
    <!-- shoulder = 1 -->
    <!-- arm = 2-->
    <!-- forearm = 3 -->
    <!-- wrist = 4 -->
    <!--arm_mico       		5 -->
    <!--   arm_half1 (7dof)		6 -->
    <!--   arm_half2 (7dof)		7 -->
    <!--   wrist_spherical_1  8 -->
    <!--   wrist_spherical_2  9 -->
    <!--   forearm_mico  10 -->
    <!-- hand 3 finger = 55 -->
    <inertial>
      <mass value="0.727"/>
      <origin xyz="0 0 -0.06"/>
      <!-- z Axis -->
      <inertia ixx="0.0003453236187" ixy="0" ixz="0" iyy="0.0003453236187" iyz="0" izz="0.0005816"/>
      <!-- y Axis -->
      <!-- x Axis -->
    </inertial>
    <!-- hand 2 finger = 56 -->
    <!-- finger_proximal = 57 -->
    <!-- finger_distal = 58 -->
  </link>
  <joint name="j2s7s300_joint_7" type="continuous">
    <parent link="j2s7s300_link_6"/>
    <child link="j2s7s300_link_7"/>
    <axis xyz="0 0 1"/>
    <limit effort="2000" lower="-6.28318530718" upper="6.28318530718" velocity="1"/>
    <origin rpy="-1.57079632679 0 3.14159265359" xyz="0 0.10375 0"/>
    <dynamics damping="0.0" friction="0.0"/>
  </joint>
  <transmission name="j2s7s300_joint_7_trans">
    <type>transmission_interface/SimpleTransmission</type>
    <joint name="j2s7s300_joint_7">
      <hardwareInterface>EffortJointInterface</hardwareInterface>
    </joint>
    <actuator name="j2s7s300_joint_7_actuator">
      <hardwareInterface>EffortJointInterface</hardwareInterface>
      <mechanicalReduction>160</mechanicalReduction>
    </actuator>
  </transmission>
  <link name="j2s7s300_end_effector">
    <visual>
      <geometry>
        <box size="0 0 0"/>
      </geometry>
    </visual>
    <collision>
      <geometry>
        <box size="0 0 0"/>
      </geometry>
    </collision>
  </link>
  <joint name="j2s7s300_joint_end_effector" type="fixed">
    <parent link="j2s7s300_link_7"/>
    <child link="j2s7s300_end_effector"/>
    <axis xyz="0 0 0"/>
    <limit effort="2000" lower="0" upper="0" velocity="1"/>
    <origin rpy="3.14159265359 0 0" xyz="0 0 -0.1600"/>
  </joint>
  <!-- finger1 Rot := Ry((1/2)*Pi) . Rx(12.1*((1/180)*Pi)+Pi) . Rz(-52.8*((1/180)*Pi)) -->
  <link name="j2s7s300_link_finger_1">
    <visual>
      <geometry>
        <mesh filename="package://kinova_description/meshes/finger_proximal.dae"/>
      </geometry>
      <material name="carbon_fiber">
        <color rgba="0.792156862745098 0.819607843137255 0.933333333333333 1"/>
      </material>
    </visual>
    <!-- Adding ring to the model -->
    <collision>
      <geometry>
        <mesh filename="package://kinova_description/meshes/finger_proximal.dae"/>
      </geometry>
    </collision>
    <!-- base = 0 -->
    <!-- shoulder = 1 -->
    <!-- arm = 2-->
    <!-- forearm = 3 -->
    <!-- wrist = 4 -->
    <!--arm_mico       		5 -->
    <!--   arm_half1 (7dof)		6 -->
    <!--   arm_half2 (7dof)		7 -->
    <!--   wrist_spherical_1  8 -->
    <!--   wrist_spherical_2  9 -->
    <!--   forearm_mico  10 -->
    <!-- hand 3 finger = 55 -->
    <!-- hand 2 finger = 56 -->
    <!-- finger_proximal = 57 -->
    <inertial>
      <mass value="0.01"/>
      <origin xyz="0.022 0 0"/>
      <!-- z Axis -->
      <inertia ixx="7.8999684e-07" ixy="0" ixz="0" iyy="7.8999684e-07" iyz="0" izz="8e-08"/>
      <!-- y Axis -->
      <!-- x Axis -->
    </inertial>
    <!-- finger_distal = 58 -->
  </link>
  <joint name="j2s7s300_joint_finger_1" type="revolute">
    <parent link="j2s7s300_link_7"/>
    <child link="j2s7s300_link_finger_1"/>
    <axis xyz="0 0 1"/>
    <origin rpy="-1.570796327 .649262481663582 1.35961148639407" xyz="0.00279 0.03126 -0.11467"/>
    <limit effort="2000" lower="0" upper="2" velocity="1"/>
  </joint>
  <transmission name="j2s7s300_joint_finger_1_trans">
    <type>transmission_interface/SimpleTransmission</type>
    <joint name="j2s7s300_joint_finger_1">
      <hardwareInterface>EffortJointInterface</hardwareInterface>
    </joint>
    <actuator name="j2s7s300_joint_finger_1_actuator">
      <hardwareInterface>EffortJointInterface</hardwareInterface>
      <mechanicalReduction>1</mechanicalReduction>
    </actuator>
  </transmission>
  <link name="j2s7s300_link_finger_tip_1">
    <visual>
      <geometry>
        <mesh filename="package://kinova_description/meshes/finger_distal.dae"/>
      </geometry>
      <material name="carbon_fiber">
        <color rgba="0.792156862745098 0.819607843137255 0.933333333333333 1"/>
      </material>
    </visual>
    <!-- Adding ring to the model -->
    <collision>
      <geometry>
        <mesh filename="package://kinova_description/meshes/finger_distal.dae"/>
      </geometry>
    </collision>
    <!-- base = 0 -->
    <!-- shoulder = 1 -->
    <!-- arm = 2-->
    <!-- forearm = 3 -->
    <!-- wrist = 4 -->
    <!--arm_mico       		5 -->
    <!--   arm_half1 (7dof)		6 -->
    <!--   arm_half2 (7dof)		7 -->
    <!--   wrist_spherical_1  8 -->
    <!--   wrist_spherical_2  9 -->
    <!--   forearm_mico  10 -->
    <!-- hand 3 finger = 55 -->
    <!-- hand 2 finger = 56 -->
    <!-- finger_proximal = 57 -->
    <!-- finger_distal = 58 -->
    <inertial>
      <mass value="0.01"/>
      <origin xyz="0.022 0 0"/>
      <!-- z Axis -->
      <inertia ixx="7.8999684e-07" ixy="0" ixz="0" iyy="7.8999684e-07" iyz="0" izz="8e-08"/>
      <!-- y Axis -->
      <!-- x Axis -->
    </inertial>
  </link>
  <joint name="j2s7s300_joint_finger_tip_1" type="fixed">
    <parent link="j2s7s300_link_finger_1"/>
    <child link="j2s7s300_link_finger_tip_1"/>
    <axis xyz="0 0 1"/>
    <origin rpy="0 0 0" xyz="0.044 -0.003 0"/>
    <limit effort="2000" lower="0" upper="2" velocity="1"/>
  </joint>
  <!-- finger2 Rot := Ry((1/2)*Pi) . Rx(10.58*((1/180)*Pi)) . Rz(-52.8*((1/180)*Pi)) -->
  <link name="j2s7s300_link_finger_2">
    <visual>
      <geometry>
        <mesh filename="package://kinova_description/meshes/finger_proximal.dae"/>
      </geometry>
      <material name="carbon_fiber">
        <color rgba="0.792156862745098 0.819607843137255 0.933333333333333 1"/>
      </material>
    </visual>
    <!-- Adding ring to the model -->
    <collision>
      <geometry>
        <mesh filename="package://kinova_description/meshes/finger_proximal.dae"/>
      </geometry>
    </collision>
    <!-- base = 0 -->
    <!-- shoulder = 1 -->
    <!-- arm = 2-->
    <!-- forearm = 3 -->
    <!-- wrist = 4 -->
    <!--arm_mico       		5 -->
    <!--   arm_half1 (7dof)		6 -->
    <!--   arm_half2 (7dof)		7 -->
    <!--   wrist_spherical_1  8 -->
    <!--   wrist_spherical_2  9 -->
    <!--   forearm_mico  10 -->
    <!-- hand 3 finger = 55 -->
    <!-- hand 2 finger = 56 -->
    <!-- finger_proximal = 57 -->
    <inertial>
      <mass value="0.01"/>
      <origin xyz="0.022 0 0"/>
      <!-- z Axis -->
      <inertia ixx="7.8999684e-07" ixy="0" ixz="0" iyy="7.8999684e-07" iyz="0" izz="8e-08"/>
      <!-- y Axis -->
      <!-- x Axis -->
    </inertial>
    <!-- finger_distal = 58 -->
  </link>
  <joint name="j2s7s300_joint_finger_2" type="revolute">
    <parent link="j2s7s300_link_7"/>
    <child link="j2s7s300_link_finger_2"/>
    <axis xyz="0 0 1"/>
    <origin rpy="-1.570796327 .649262481663582 -1.38614049188413" xyz="0.02226 -0.02707 -0.11482"/>
    <limit effort="2000" lower="0" upper="2" velocity="1"/>
  </joint>
  <transmission name="j2s7s300_joint_finger_2_trans">
    <type>transmission_interface/SimpleTransmission</type>
    <joint name="j2s7s300_joint_finger_2">
      <hardwareInterface>EffortJointInterface</hardwareInterface>
    </joint>
    <actuator name="j2s7s300_joint_finger_2_actuator">
      <hardwareInterface>EffortJointInterface</hardwareInterface>
      <mechanicalReduction>1</mechanicalReduction>
    </actuator>
  </transmission>
  <link name="j2s7s300_link_finger_tip_2">
    <visual>
      <geometry>
        <mesh filename="package://kinova_description/meshes/finger_distal.dae"/>
      </geometry>
      <material name="carbon_fiber">
        <color rgba="0.792156862745098 0.819607843137255 0.933333333333333 1"/>
      </material>
    </visual>
    <!-- Adding ring to the model -->
    <collision>
      <geometry>
        <mesh filename="package://kinova_description/meshes/finger_distal.dae"/>
      </geometry>
    </collision>
    <!-- base = 0 -->
    <!-- shoulder = 1 -->
    <!-- arm = 2-->
    <!-- forearm = 3 -->
    <!-- wrist = 4 -->
    <!--arm_mico       		5 -->
    <!--   arm_half1 (7dof)		6 -->
    <!--   arm_half2 (7dof)		7 -->
    <!--   wrist_spherical_1  8 -->
    <!--   wrist_spherical_2  9 -->
    <!--   forearm_mico  10 -->
    <!-- hand 3 finger = 55 -->
    <!-- hand 2 finger = 56 -->
    <!-- finger_proximal = 57 -->
    <!-- finger_distal = 58 -->
    <inertial>
      <mass value="0.01"/>
      <origin xyz="0.022 0 0"/>
      <!-- z Axis -->
      <inertia ixx="7.8999684e-07" ixy="0" ixz="0" iyy="7.8999684e-07" iyz="0" izz="8e-08"/>
      <!-- y Axis -->
      <!-- x Axis -->
    </inertial>
  </link>
  <joint name="j2s7s300_joint_finger_tip_2" type="fixed">
    <parent link="j2s7s300_link_finger_2"/>
    <child link="j2s7s300_link_finger_tip_2"/>
    <axis xyz="0 0 1"/>
    <origin rpy="0 0 0" xyz="0.044 -0.003 0"/>
    <limit effort="2000" lower="0" upper="2" velocity="1"/>
  </joint>
  <!-- finger3 Rot := Ry((1/2)*Pi) . Rx(-10.58*((1/180)*Pi)) . Rz(-52.8*((1/180)*Pi)) -->
  <link name="j2s7s300_link_finger_3">
    <visual>
      <geometry>
        <mesh filename="package://kinova_description/meshes/finger_proximal.dae"/>
      </geometry>
      <material name="carbon_fiber">
        <color rgba="0.792156862745098 0.819607843137255 0.933333333333333 1"/>
      </material>
    </visual>
    <!-- Adding ring to the model -->
    <collision>
      <geometry>
        <mesh filename="package://kinova_description/meshes/finger_proximal.dae"/>
      </geometry>
    </collision>
    <!-- base = 0 -->
    <!-- shoulder = 1 -->
    <!-- arm = 2-->
    <!-- forearm = 3 -->
    <!-- wrist = 4 -->
    <!--arm_mico       		5 -->
    <!--   arm_half1 (7dof)		6 -->
    <!--   arm_half2 (7dof)		7 -->
    <!--   wrist_spherical_1  8 -->
    <!--   wrist_spherical_2  9 -->
    <!--   forearm_mico  10 -->
    <!-- hand 3 finger = 55 -->
    <!-- hand 2 finger = 56 -->
    <!-- finger_proximal = 57 -->
    <inertial>
      <mass value="0.01"/>
      <origin xyz="0.022 0 0"/>
      <!-- z Axis -->
      <inertia ixx="7.8999684e-07" ixy="0" ixz="0" iyy="7.8999684e-07" iyz="0" izz="8e-08"/>
      <!-- y Axis -->
      <!-- x Axis -->
    </inertial>
    <!-- finger_distal = 58 -->
  </link>
  <joint name="j2s7s300_joint_finger_3" type="revolute">
    <parent link="j2s7s300_link_7"/>
    <child link="j2s7s300_link_finger_3"/>
    <axis xyz="0 0 1"/>
    <origin rpy="-1.570796327 .649262481663582 -1.75545216211587" xyz="-0.02226 -0.02707 -0.11482"/>
    <limit effort="2000" lower="0" upper="2" velocity="1"/>
  </joint>
  <transmission name="j2s7s300_joint_finger_3_trans">
    <type>transmission_interface/SimpleTransmission</type>
    <joint name="j2s7s300_joint_finger_3">
      <hardwareInterface>EffortJointInterface</hardwareInterface>
    </joint>
    <actuator name="j2s7s300_joint_finger_3_actuator">
      <hardwareInterface>EffortJointInterface</hardwareInterface>
      <mechanicalReduction>1</mechanicalReduction>
    </actuator>
  </transmission>
  <link name="j2s7s300_link_finger_tip_3">
    <visual>
      <geometry>
        <mesh filename="package://kinova_description/meshes/finger_distal.dae"/>
      </geometry>
      <material name="carbon_fiber">
        <color rgba="0.792156862745098 0.819607843137255 0.933333333333333 1"/>
      </material>
    </visual>
    <!-- Adding ring to the model -->
    <collision>
      <geometry>
        <mesh filename="package://kinova_description/meshes/finger_distal.dae"/>
      </geometry>
    </collision>
    <!-- base = 0 -->
    <!-- shoulder = 1 -->
    <!-- arm = 2-->
    <!-- forearm = 3 -->
    <!-- wrist = 4 -->
    <!--arm_mico       		5 -->
    <!--   arm_half1 (7dof)		6 -->
    <!--   arm_half2 (7dof)		7 -->
    <!--   wrist_spherical_1  8 -->
    <!--   wrist_spherical_2  9 -->
    <!--   forearm_mico  10 -->
    <!-- hand 3 finger = 55 -->
    <!-- hand 2 finger = 56 -->
    <!-- finger_proximal = 57 -->
    <!-- finger_distal = 58 -->
    <inertial>
      <mass value="0.01"/>
      <origin xyz="0.022 0 0"/>
      <!-- z Axis -->
      <inertia ixx="7.8999684e-07" ixy="0" ixz="0" iyy="7.8999684e-07" iyz="0" izz="8e-08"/>
      <!-- y Axis -->
      <!-- x Axis -->
    </inertial>
  </link>
  <joint name="j2s7s300_joint_finger_tip_3" type="fixed">
    <parent link="j2s7s300_link_finger_3"/>
    <child link="j2s7s300_link_finger_tip_3"/>
    <axis xyz="0 0 1"/>
    <origin rpy="0 0 0" xyz="0.044 -0.003 0"/>
    <limit effort="2000" lower="0" upper="2" velocity="1"/>
  </joint>
  <!--  <xacro:include filename="$(find table_basket)/urdf/kinect_box.urdf.xacro" />-->
  <!-- define the table and baskets-->
  <link name="table">
    <inertial>
      <origin rpy="0 0 0" xyz="0 0 0"/>
      <mass value="81.416"/>
      <inertia ixx="17.674" ixy="-4.3368E-16" ixz="4.9467E-16" iyy="17.674" iyz="1.3081E-17" izz="19.456"/>
    </inertial>
    <visual>
      <origin rpy="0 0 0" xyz="0 0 0"/>
      <geometry>
        <mesh filename="package://table_basket/meshes/table.STL"/>
      </geometry>
      <material name="">
        <color rgba="1 1 1 1"/>
        <texture filename="package://table_basket/textures/table_color.jpg"/>
      </material>
    </visual>
    <collision>
      <origin rpy="0 0 0" xyz="0 0 0"/>
      <geometry>
        <mesh filename="package://table_basket/meshes/table.STL"/>
      </geometry>
    </collision>
  </link>
  <link name="left_basket">
    <inertial>
      <origin rpy="0 0 0" xyz="-1.1102E-16 0 0.031586"/>
      <mass value="1.8812"/>
      <inertia ixx="0.029288" ixy="-2.2695E-18" ixz="-2.6278E-18" iyy="0.01841" iyz="2.5457E-20" izz="0.04459"/>
    </inertial>
    <visual>
      <origin rpy="0 0 0" xyz="0 0 0"/>
      <geometry>
        <mesh filename="package://table_basket/meshes/left_basket.STL"/>
      </geometry>
      <material name="">
        <color rgba="1 1 1 1"/>
        <texture filename="package://table_basket/textures/blue.jpg"/>
      </material>
    </visual>
    <collision>
      <origin rpy="0 0 0" xyz="0 0 0"/>
      <geometry>
        <mesh filename="package://table_basket/meshes/left_basket.STL"/>
      </geometry>
    </collision>
  </link>
  <joint name="left_fix" type="fixed">
    <origin rpy="0 0 0" xyz="0.27 0.275 0"/>
    <parent link="table"/>
    <child link="left_basket"/>
    <axis xyz="0 0 0"/>
  </joint>
  <link name="right_basket">
    <inertial>
      <origin rpy="0 0 0" xyz="0 -5.5511E-17 0.031586"/>
      <mass value="1.8812"/>
      <inertia ixx="0.029288" ixy="1.3977E-18" ixz="-3.7403E-18" iyy="0.01841" iyz="-5.7134E-19" izz="0.04459"/>
    </inertial>
    <visual>
      <origin rpy="0 0 0" xyz="0 0 0"/>
      <geometry>
        <mesh filename="package://table_basket/meshes/right_basket.STL"/>
      </geometry>
      <material name="">
        <color rgba="1 1 1 1"/>
        <texture filename="package://table_basket/textures/green.jpg"/>
      </material>
    </visual>
    <collision>
      <origin rpy="0 0 0" xyz="0 0 0"/>
      <geometry>
        <mesh filename="package://table_basket/meshes/right_basket.STL"/>
      </geometry>
    </collision>
  </link>
  <joint name="right_fix" type="fixed">
    <origin rpy="0 0 0" xyz="-0.27 0.275 0"/>
    <parent link="table"/>
    <child link="right_basket"/>
    <axis xyz="0 0 0"/>
  </joint>
  <link name="map"/>
  <joint name="world_joint" type="fixed">
    <parent link="map"/>
    <child link="table"/>
    <origin rpy="0.0 0.0 0.0" xyz="0.0 0.0 0.0"/>
  </joint>
  <!-- joint -->
  <joint name="robot_fix" type="fixed">
    <parent link="table"/>
    <child link="root"/>
    <origin rpy="0.0 0.0 0.0" xyz="0.0 0.0 0.0"/>
  </joint>
  <!--  <joint name="camera_fix" type="fixed">-->
  <!--    <parent link="root" />-->
  <!--    <child link="camera_base_link" />-->
  <!--    <origin rpy="0.0 1.57 -1.57" xyz="0.0 -0.5 0.8"/>-->
  <!--  </joint>-->
  <!-- gazebo 
  <gazebo reference="camera_rgb_frame">
    <sensor type="depth" name="camera">
      <always_on>true</always_on>
      <update_rate>15.0</update_rate>
      <camera>
        <horizontal_fov>1.047197</horizontal_fov>
        <image>  -->
  <!-- openni_kinect plugin works only with BGR8
          <format>B8G8R8</format>
          <width>800</width>
          <height>800</height>
        </image>
        <clip>
          <near>0.05</near>
          <far>50</far>
        </clip>
      </camera>
    <plugin name="camera_link_controller" filename="libgazebo_ros_openni_kinect.so">
      <baseline>0.1</baseline>
      <alwaysOn>true</alwaysOn>
      <updateRate>15.0</updateRate>
      <cameraName>kinect</cameraName>
      <imageTopicName>/kinect/rgb/image_raw</imageTopicName>
      <cameraInfoTopicName>/kinect/rgb/camera_info</cameraInfoTopicName>
      <depthImageTopicName>/kinect/rgb/image_raw</depthImageTopicName>
      <depthImageCameraInfoTopicName>/kinect/rgb/camera_info</depthImageCameraInfoTopicName>
      <pointCloudTopicName>/kinect/rgb/points</pointCloudTopicName>
      <frameName>camera_rgb_optical_frame</frameName>
      <pointCloudCutoff>0.35</pointCloudCutoff>
      <pointCloudCutoffMax>4.5</pointCloudCutoffMax>
      <CxPrime>0</CxPrime>
      <Cx>0</Cx>
      <Cy>0</Cy>
      <focalLength>0</focalLength>
      <hackBaseline>0</hackBaseline>
    </plugin>
   </sensor>
  </gazebo> -->
</robot>

